<?xml version="1.0"?>
<sdf version="1.8">
  <model name="simple_quadcopter">
    <link name="base_link">
      <inertial>
        <mass>1.0</mass>
        <inertia>
          <ixx>0.01</ixx>
          <ixy>0.0</ixy>
          <ixz>0.0</ixz>
          <iyy>0.01</iyy>
          <iyz>0.0</iyz>
          <izz>0.01</izz>
        </inertia>
      </inertial>
      <collision name="collision">
        <geometry>
          <box>
            <size>0.2 0.2 0.05</size>
          </box>
        </geometry>
      </collision>
      <visual name="visual">
        <geometry>
          <box>
            <size>0.2 0.2 0.05</size>
          </box>
        </geometry>
      </visual>
    </link>

    <link name="rotor_0_link">
      <pose>0.1 0.1 0.0 0 0 0</pose>
      <inertial>
        <mass>0.01</mass>
        <inertia>
          <ixx>0.0001</ixx>
          <ixy>0.0</ixy>
          <ixz>0.0</ixz>
          <iyy>0.0001</iyy>
          <iyz>0.0</iyz>
          <izz>0.0001</izz>
        </inertia>
      </inertial>
      <collision name="collision">
        <geometry>
          <cylinder>
            <radius>0.05</radius>
            <length>0.01</length>
          </cylinder>
        </geometry>
      </collision>
      <visual name="visual">
        <geometry>
          <cylinder>
            <radius>0.05</radius>
            <length>0.01</length>
          </cylinder>
        </geometry>
      </visual>
    </link>
    <joint name="rotor_0_joint" type="revolute">
      <parent>base_link</parent>
      <child>rotor_0_link</child>
      <axis>
        <xyz>0 0 1</xyz>
      </axis>
    </joint>

    <link name="rotor_1_link">
      <pose>0.1 -0.1 0.0 0 0 0</pose>
      <inertial>
        <mass>0.01</mass>
        <inertia>
          <ixx>0.0001</ixx>
          <ixy>0.0</ixy>
          <ixz>0.0</ixz>
          <iyy>0.0001</iyy>
          <iyz>0.0</iyz>
          <izz>0.0001</izz>
        </inertia>
      </inertial>
      <collision name="collision">
        <geometry>
          <cylinder>
            <radius>0.05</radius>
            <length>0.01</length>
          </cylinder>
        </geometry>
      </collision>
      <visual name="visual">
        <geometry>
          <cylinder>
            <radius>0.05</radius>
            <length>0.01</length>
          </cylinder>
        </geometry>
      </visual>
    </link>
    <joint name="rotor_1_joint" type="revolute">
      <parent>base_link</parent>
      <child>rotor_1_link</child>
      <axis>
        <xyz>0 0 1</xyz>
      </axis>
    </joint>

    <link name="rotor_2_link">
      <pose>-0.1 -0.1 0.0 0 0 0</pose>
      <inertial>
        <mass>0.01</mass>
        <inertia>
          <ixx>0.0001</ixx>
          <ixy>0.0</ixy>
          <ixz>0.0</ixz>
          <iyy>0.0001</iyy>
          <iyz>0.0</iyz>
          <izz>0.0001</izz>
        </inertia>
      </inertial>
      <collision name="collision">
        <geometry>
          <cylinder>
            <radius>0.05</radius>
            <length>0.01</length>
          </cylinder>
        </geometry>
      </collision>
      <visual name="visual">
        <geometry>
          <cylinder>
            <radius>0.05</radius>
            <length>0.01</length>
          </cylinder>
        </geometry>
      </visual>
    </link>
    <joint name="rotor_2_joint" type="revolute">
      <parent>base_link</parent>
      <child>rotor_2_link</child>
      <axis>
        <xyz>0 0 1</xyz>
      </axis>
    </joint>

    <link name="rotor_3_link">
      <pose>-0.1 0.1 0.0 0 0 0</pose>
      <inertial>
        <mass>0.01</mass>
        <inertia>
          <ixx>0.0001</ixx>
          <ixy>0.0</ixy>
          <ixz>0.0</ixz>
          <iyy>0.0001</iyy>
          <iyz>0.0</iyz>
          <izz>0.0001</izz>
        </inertia>
      </inertial>
      <collision name="collision">
        <geometry>
          <cylinder>
            <radius>0.05</radius>
            <length>0.01</length>
          </cylinder>
        </geometry>
      </collision>
      <visual name="visual">
        <geometry>
          <cylinder>
            <radius>0.05</radius>
            <length>0.01</length>
          </cylinder>
        </geometry>
      </visual>
    </link>
    <joint name="rotor_3_joint" type="revolute">
      <parent>base_link</parent>
      <child>rotor_3_link</child>
      <axis>
        <xyz>0 0 1</xyz>
      </axis>
    </joint>

  </model>
</sdf>